Workbook

Sheet Overzicht
A1: ParkingYou Fundament — voortgang
A2: Gegenereerd uit Projectplan_v1.0.md. Werk de kolom Status bij op het blad Takenlijst.
A4: Fase | B4: Periode | C4: Taken | D4: Gereed | E4: Voortgang | F4: Uren R+C | G4: Uren domein | H4: Uren directie | I4: Uren totaal
A5: 0 · Fundament | B5: week 1–4 | C5: 52 | D5: =COUNTIF(Takenlijst!I2:I53,"Gereed") | E5: =IF(C5=0,0,D5/C5) | F5: 36 | G5: 53 | H5: 20 | I5: =SUM(F5:H5)
A6: 1 · Abonnementen | B6: week 4–8 | C6: 22 | D6: =COUNTIF(Takenlijst!I54:I75,"Gereed") | E6: =IF(C6=0,0,D6/C6) | F6: 21 | G6: 30 | H6: 2 | I6: =SUM(F6:H6)
A7: 2 · Eerste koppeling | B7: week 6–14 | C7: 25 | D7: =COUNTIF(Takenlijst!I76:I100,"Gereed") | E7: =IF(C7=0,0,D7/C7) | F7: 48.5 | G7: 22 | H7: 0 | I7: =SUM(F7:H7)
A8: 3 · Uitrollen | B8: maand 4–7 | C8: 28 | D8: =COUNTIF(Takenlijst!I101:I128,"Gereed") | E8: =IF(C8=0,0,D8/C8) | F8: 116 | G8: 37 | H8: 3 | I8: =SUM(F8:H8)
A9: 4 · Klantenservice | B9: maand 6–9 | C9: 22 | D9: =COUNTIF(Takenlijst!I129:I150,"Gereed") | E9: =IF(C9=0,0,D9/C9) | F9: 34 | G9: 87 | H9: 2 | I9: =SUM(F9:H9)
A10: 5 · Automatiseren | B10: maand 9–12 | C10: 26 | D10: =COUNTIF(Takenlijst!I151:I176,"Gereed") | E10: =IF(C10=0,0,D10/C10) | F10: 112 | G10: 45 | H10: 1 | I10: =SUM(F10:H10)
A11: Totaal | C11: =SUM(C5:C10) | D11: =SUM(D5:D10) | E11: =IF(C11=0,0,D11/C11) | F11: =SUM(F5:F10) | G11: =SUM(G5:G10) | H11: =SUM(H5:H10) | I11: =SUM(I5:I10)
A13: Mijlpalen
A14: Gehaald | C14: =COUNTIF(Mijlpalen!H2:H13,"Gehaald") & " van 12"
A16: Let op
A17: De leveranciersaanvragen (taken 0.3 t/m 0.6) bepalen de doorlooptijd van het hele project.
A18: Zet ze in week 1 op "Wacht op derden" en bewaak ze — niets in fase 2 en 3 kan zonder.
A19: Een mijlpaal is pas gehaald als het testscript in Mijlpaal_Testrapporten.md klopt,
A20: niet als de taken zijn afgevinkt. De aftekenaar is nooit de bouwer.

Sheet Takenlijst
A1: Nr | B1: Fase | C1: Blok | D1: Taak | E1: Eigenaar | F1: Uren | G1: Hangt af van | H1: Mijlpaal | I1: Status | J1: Gereed op | K1: Opmerking
A2: 0.1 | B2: 0 · Fundament | C2: 0A Het kritieke pad — deze week de deur uit | D2: Contactpersonen achterhalen bij SKIDATA, IP Parking, Scheidt & Bachmann, Aeroparker | E2: R | F2: 2 | I2: Niet gestart
A3: 0.2 | B3: 0 · Fundament | C3: 0A Het kritieke pad — deze week de deur uit | D3: Aanvraagbrief opstellen per leverancier (sjabloon in 02_WERKMATERIAAL) | E3: C | F3: 1 | G3: 0.1 | I3: Niet gestart
A4: 0.3 | B4: 0 · Fundament | C4: 0A Het kritieke pad — deze week de deur uit | D4: Aanvraag versturen naar SKIDATA — API/export, formaten, kosten, voorwaarden | E4: R | F4: 0.5 | G4: 0.2 | I4: Niet gestart
A5: 0.4 | B5: 0 · Fundament | C5: 0A Het kritieke pad — deze week de deur uit | D5: Aanvraag versturen naar IP Parking | E5: R | F5: 0.5 | G5: 0.2 | I5: Niet gestart
A6: 0.5 | B6: 0 · Fundament | C6: 0A Het kritieke pad — deze week de deur uit | D6: Aanvraag versturen naar Scheidt & Bachmann | E6: R | F6: 0.5 | G6: 0.2 | I6: Niet gestart
A7: 0.6 | B7: 0 · Fundament | C7: 0A Het kritieke pad — deze week de deur uit | D7: Aanvraag versturen naar Aeroparker | E7: R | F7: 0.5 | G7: 0.2 | I7: Niet gestart
A8: 0.7 | B8: 0 · Fundament | C8: 0A Het kritieke pad — deze week de deur uit | D8: AFAS-consultant benaderen: welke connectoren zitten in onze licentie, doet AFAS al facturatie/incasso? | E8: R | F8: 1 | I8: Niet gestart
A9: 0.8 | B9: 0 · Fundament | C9: 0A Het kritieke pad — deze week de deur uit | D9: Zendesk: huidige inrichting en API-mogelijkheden in kaart brengen | E9: D3 | F9: 2 | I9: Niet gestart
A10: 0.9 | B10: 0 · Fundament | C10: 0A Het kritieke pad — deze week de deur uit | D10: Aanvraagdata vastleggen in `connector.aanvraag_verstuurd_op` | E10: R | F10: 0.5 | G10: 0.3–0.6 | H10: M0 | I10: Niet gestart
A11: 0.10 | B11: 0 · Fundament | C11: 0A Het kritieke pad — deze week de deur uit | D11: Herinnering inplannen: geen antwoord na 10 werkdagen = nabellen | E11: R | F11: 0.25 | G11: 0.9 | I11: Niet gestart
A12: 0.11 | B12: 0 · Fundament | C12: 0B Besluiten en mandaat | D12: Besluit 1 en 2 formeel vastleggen in het besluitenlogboek | E12: DIR | F12: 1 | I12: Niet gestart
A13: 0.12 | B13: 0 · Fundament | C13: 0B Besluiten en mandaat | D13: Besluit 3 (automatiseringslaag) bevestigen of afwijzen | E13: R+DIR | F13: 1 | I13: Niet gestart
A14: 0.13 | B14: 0 · Fundament | C14: 0B Besluiten en mandaat | D14: Besluit 6 (SharePoint-teamsite, Notion uitfaseren) nemen, mét einddatum voor Notion | E14: DIR | F14: 1 | I14: Niet gestart
A15: 0.14 | B15: 0 · Fundament | C15: 0B Besluiten en mandaat | D15: Zeven domeineigenaren formeel aanwijzen — rol, niet persoon | E15: DIR | F15: 2 | I15: Niet gestart
A16: 0.15 | B16: 0 · Fundament | C16: 0B Besluiten en mandaat | D16: Kick-off met de domeineigenaren: wat verandert er, wat wordt van hen verwacht | E16: R | F16: 3 | G16: 0.14 | I16: Niet gestart
A17: 0.16 | B17: 0 · Fundament | C17: 0B Besluiten en mandaat | D17: Afspraak vastleggen: 2 uur per week per domeineigenaar, in de agenda | E17: DIR | F17: 1 | G17: 0.15 | I17: Niet gestart
A18: 0.17 | B18: 0 · Fundament | C18: 0B Besluiten en mandaat | D18: Bevriezingsdatum oude drive afspreken en communiceren | E18: DIR | F18: 1 | G18: 0.14 | I18: Niet gestart
A19: 0.18 | B19: 0 · Fundament | C19: 0B Besluiten en mandaat | D19: Maandelijks voortgangsoverleg inplannen voor de hele looptijd | E19: R | F19: 0.5 | G19: 0.14 | I19: Niet gestart
A20: 0.19 | B20: 0 · Fundament | C20: 0C De datalaag opzetten | D20: Supabase-project `parkingyou-productie` aanmaken (eu-central-1) | E20: R | F20: 0.5 | G20: 0.11 | I20: Niet gestart
A21: 0.20 | B21: 0 · Fundament | C21: 0C De datalaag opzetten | D21: Migraties 0001–0011 toepassen | E21: C | F21: 0.5 | G21: 0.19 | I21: Niet gestart
A22: 0.21 | B22: 0 · Fundament | C22: 0C De datalaag opzetten | D22: `seed_referentiedata.sql` laden (Connector Registry) | E22: C | F22: 0.25 | G22: 0.20 | I22: Niet gestart
A23: 0.22 | B23: 0 · Fundament | C23: 0C De datalaag opzetten | D23: Schema controleren: 29 tabellen, 11 weergaven, RLS actief | E23: C | F23: 0.5 | G23: 0.20 | I23: Niet gestart
A24: 0.23 | B24: 0 · Fundament | C24: 0C De datalaag opzetten | D24: Domeinrollen aanmaken met inlogaccounts; wachtwoorden in de kluis | E24: R | F24: 1 | G24: 0.20 | I24: Niet gestart
A25: 0.24 | B25: 0 · Fundament | C25: 0C De datalaag opzetten | D25: Automatische back-up controleren en bewaartermijn instellen | E25: R | F25: 0.5 | G25: 0.19 | I25: Niet gestart
A26: 0.25 | B26: 0 · Fundament | C26: 0C De datalaag opzetten | D26: Supabase-branch `test` aanmaken voor het oefenen van mijlpalen | E26: C | F26: 0.5 | G26: 0.20 | I26: Niet gestart
A27: 0.26 | B27: 0 · Fundament | C27: 0D De formulierlaag | D27: NocoDB opzetten (cloud of self-hosted) en verbinden met Supabase | E27: R+C | F27: 3 | G27: 0.23 | I27: Niet gestart
... A31: 0.30 | B31: 0 · Fundament | C31: 0D De formulierlaag | D31: Inloggegevens uitdelen en per domeineigenaar 30 minuten uitleg geven | E31: R | F31: 4 | G31: 0.28 | I31: Niet gestart
A32: 0.31 | B32: 0 · Fundament | C32: 0E Uitzoekwerk dat besluiten blokkeert | D32: Meldkamer in kaart brengen: wat doen ze, wat registreren ze, waar landt het, is het te ontsluiten? | E32: D2 | F32: 4 | I32: Niet gestart
A33: 0.32 | B33: 0 · Fundament | C33: 0E Uitzoekwerk dat besluiten blokkeert | D33: Bestaan er prognoses per locatie? Zo ja, waar en hoe gemaakt? | E33: D1 | F33: 2 | I33: Niet gestart
A34: 0.33 | B34: 0 · Fundament | C34: 0E Uitzoekwerk dat besluiten blokkeert | D34: Inventariseren welk parkeersysteem op hoeveel locaties draait (bepaalt de pilot) | E34: D2 | F34: 2 | I34: Niet gestart
A35: 0.34 | B35: 0 · Fundament | C35: 0E Uitzoekwerk dat besluiten blokkeert | D35: AVG: verwerkingsregister actualiseren voor de nieuwe datalaag | E35: DIR | F35: 3 | G35: 0.20 | I35: Niet gestart
A36: 0.35 | B36: 0 · Fundament | C36: 0E Uitzoekwerk dat besluiten blokkeert | D36: AVG: bewaartermijn kentekens en abonneegegevens na opzegging vastleggen | E36: DIR | F36: 2 | G36: 0.34 | I36: Niet gestart
A37: 0.36 | B37: 0 · Fundament | C37: 0E Uitzoekwerk dat besluiten blokkeert | D37: AVG: verwerkersovereenkomst met Supabase controleren en archiveren | E37: DIR | F37: 1 | G37: 0.19 | I37: Niet gestart
A38: 0.37 | B38: 0 · Fundament | C38: 0F De registers vullen | D38: Locatiesjabloon invullen: 37 locaties, basisgegevens | E38: D2 | F38: 6 | G38: 0.28 | I38: Niet gestart
A39: 0.38 | B39: 0 · Fundament | C39: 0F De registers vullen | D39: Per locatie het dienstverleningstype bepalen (exploitatie/advies/onderhoud/beheer) | E39: D2+DIR | F39: 2 | G39: 0.37 | I39: Niet gestart
A40: 0.39 | B40: 0 · Fundament | C40: 0F De registers vullen | D40: Per locatie de systeempartner en het externe locatie-ID vastleggen | E40: D2 | F40: 3 | G40: 0.37 | I40: Niet gestart
A41: 0.40 | B41: 0 · Fundament | C41: 0F De registers vullen | D41: Per locatie de contractpartijen vastleggen, inclusief wie primair contact is | E41: DIR | F41: 4 | G41: 0.37 | I41: Niet gestart
A42: 0.41 | B42: 0 · Fundament | C42: 0F De registers vullen | D42: Lopende contracten koppelen aan locaties, met documentlink naar SharePoint | E42: DIR | F42: 4 | G42: 0.40 | I42: Niet gestart
A43: 0.42 | B43: 0 · Fundament | C43: 0F De registers vullen | D43: Parkeerhosts invoeren en aan locaties koppelen | E43: D2 | F43: 2 | G43: 0.37 | I43: Niet gestart
...

Sheet Mijlpalen
A1: Mijlpaal | B1: Fase | C1: Wat er dan staat | D1: Tekent af | E1: Sluit af na taak | F1: Testcriterium | G1: Voortgang t/m | H1: Status | I1: Afgetekend op
A2: M0 | B2: 0 · Fundament | C2: Besluiten genomen, kritiek pad gestart | D2: Directie | E2: 0.9 | F2: Vier leveranciersaanvragen verstuurd, met datum in de Connector Registry | G2: =COUNTIF(Takenlijst!$I$2:$I$10,"Gereed")/9 | H2: Niet gehaald
A3: M1 | B3: 0 · Fundament | C3: Registers live | D3: D2 Operatie | E3: 0.44 | F3: 37 locaties compleet in NocoDB; v_datakwaliteit leeg | G3: =COUNTIF(Takenlijst!$I$2:$I$45,"Gereed")/44 | H3: Niet gehaald
A4: M2 | B4: 0 · Fundament | C4: Documentlaag live, oude drive bevroren | D4: Directie | E4: 0.52 | F4: Nieuwe SharePoint in gebruik; schrijven in de oude drive wordt geweigerd | G4: =COUNTIF(Takenlijst!$I$2:$I$53,"Gereed")/52 | H4: Niet gehaald
A5: M3 | B5: 1 · Abonnementen | C5: Abonnementen gemigreerd | D5: D3 Klantenservice | E5: 1.18 | F5: Aantallen kloppen met Excel; steekproef van tien correct; Excel bevroren | G5: =COUNTIF(Takenlijst!$I$54:$I$71,"Gereed")/18 | H5: Niet gehaald
A6: M4 | B6: 1 · Abonnementen | C6: Kentekenwijziging werkt end-to-end | D6: D3 Klantenservice | E6: 1.13 | F6: Formulier werkt; mutatie automatisch vastgelegd; werklijst loopt leeg | G6: =COUNTIF(Takenlijst!$I$54:$I$66,"Gereed")/13 | H6: Niet gehaald
A7: M5 | B7: 2 · Eerste koppeling | C7: Pilot-parkeersysteem levert data | D7: D1 Financiën | E7: 2.14 | F7: Dagelijkse run draait vanzelf; tweede import verdubbelt niet; fout geeft alarm | G7: =COUNTIF(Takenlijst!$I$76:$I$89,"Gereed")/14 | H7: Niet gehaald
A8: M6 | B8: 2 · Eerste koppeling | C8: Dashboard per locatie | D8: D1 + D2 | E8: 2.23 | F8: Dwarsdoorsnede klopt; advieslocaties tellen niet mee; prognose naar rato | G8: =COUNTIF(Takenlijst!$I$76:$I$98,"Gereed")/23 | H8: Niet gehaald
A9: M7 | B9: 3 · Uitrollen | C9: Alle platformen en AFAS gekoppeld | D9: D1 Financiën | E9: 3.8 | F9: Nul exploitatielocaties zonder data over de laatste 7 dagen | G9: =COUNTIF(Takenlijst!$I$101:$I$108,"Gereed")/8 | H9: Niet gehaald
A10: M8 | B10: 3 · Uitrollen | C10: Eigenaarsrapportages automatisch | D10: Directie | E10: 3.21 | F10: Gegenereerd, juiste naam en map, verzonden aan de primaire contactpartij | G10: =COUNTIF(Takenlijst!$I$101:$I$121,"Gereed")/21 | H10: Niet gehaald
A11: M9 | B11: 4 · Klantenservice | C11: Kanaal gekoppeld en kennisbank gevuld | D11: D3 Klantenservice | E11: 4.15 | F11: Klantvragen landen in de datalaag; top 20 vragen heeft een actueel artikel | G11: =COUNTIF(Takenlijst!$I$129:$I$143,"Gereed")/15 | H11: Niet gehaald
A12: M10 | B12: 5 · Automatiseren | C12: AI-klantenservice live | D12: D3 + Directie | E12: 5.12 | F12: Minimaal 15 van 20 testvragen correct; nul foute antwoorden zonder escalatie | G12: =COUNTIF(Takenlijst!$I$151:$I$162,"Gereed")/12 | H12: Niet gehaald
A13: M11 | B13: 5 · Automatiseren | C13: Signaallus actief | D13: Directie | E13: 5.24 | F13: Signaal → oorzaakcheck → campagne → ROI, met een uitgelokte afwijking getest | G13: =COUNTIF(Takenlijst!$I$151:$I$174,"Gereed")/24 | H13: Niet gehaald
